Workbook
Name Ciclo_Rotación_Calif: Parámetros!$C$54:$C$58
Name Ciclo_Rotación_Def: Parámetros!$B$54:$B$58
Name Impacto_Obj_Est_Calif: Parámetros!$C$30:$C$34
Name Impacto_Obj_Est_Def: Parámetros!$B$30:$B$34
Name Impacto_Ppto_Calif: Parámetros!#REF!
Name Impacto_Ppto_Def: Parámetros!#REF!
Name Nivel_Criticidad: Parámetros!$E$46:$G$50
Name Nivel_Directivo_Calif: Parámetros!$C$22:$C$26
Name Nivel_Directivo_Def: Parámetros!$B$22:$B$26
Name Nivel_Directivo_Def_PQR: Parámetros!$D$22:$D$26
Name Result_Aud_Ant_Calif: Parámetros!$C$37:$C$41
Name Result_Aud_Ant_Def: Parámetros!$B$37:$B$41
Name Tiempo_Ult_Aud_Calif: Parámetros!$E$14:$E$18
Name Tiempo_Ult_Aud_Def: Parámetros!$B$14:$B$18

Sheet Parámetros
B3: Total presupuesto egresos entidad aprobado para la vigencia | C3: 116704559235 | D3: Presupuesto de Funcionamiento 2022
A5: Puntajes | B5: Nivel riesgo inherente
A6: 1 | B6: No tiene Riesgos Asociado
A7: 2 | B7: Los riesgos estan en zona baja (zona de aceptacion)
A8: 3 | B8: Tiene un riesgo o más en Calificación Moderada
A9: 4 | B9: Tiene un riesgo o más en calificación Alta
A10: 5 | B10: Tiene un riesgo en calificación Extrema
B13: Tiempo transcurrido desde última auditoría
B14: <= 1 año | C14: 0 | D14: 1 | E14: 1
B15: > 1 año <= 2 años | C15: =D14 -> 1 | D15: 2 | E15: 2
B16: > 2 años <= 3 años | C16: =D15 -> 2 | D16: 3 | E16: 3
B17: > 3 años <= 4 años | C17: =D16 -> 3 | D17: 4 | E17: 4
B18: > 4 años | C18: =D17 -> 4 | D18: 99 | E18: 5
B21: Nivel_Directivo | D21: CANTIDAD PQR
B22: Interés poco relevante | C22: 1 | D22: Sin PQR | E22: Temas de seguimiento alta direccion con menor repeticion en un periodo de seis meses ( menos de 2 seguimientos en diferentes comites)
B23: Interés bajo | C23: 2 | D23: Con peticiones en terminos | E23: Temas de seguimiento alta direccion con penúltimo valor de repeticion en un periodo de seis meses( entre 2 y 3 seguimientos en diferentes comites)
B24: Interés medio | C24: 3 | D24: Con Reclamo (s) | E24: Temas de seguimiento alta direccion con ante peúltimo valor de repeticion en un periodo de seis meses ( entre 4 y 5 seguimientos en diferentes comites)
B25: Interés alto | C25: 4 | D25: Con peticiones extemporaneas | E25: Temas de seguimiento alta direccion con el segundo mayor valor de repeticion en un periodo de seis meses( entre 6 y 7 seguimientos en diferentes comites)
B26: Interés muy relevante | C26: 5 | D26: Con denuncia (s) | E26: Temas de seguimiento alta direccion con el mayor valor de repeticion en un periodo de seis meses ( 8 o mas seguimientos en diferentes comites)
B29: Objetivos estratégicos asociados
B30: No tiene objetivo asociado | C30: 1
B31: 1 objetivo estratégico asociado | C31: 2
B32: 2 objetivos estratégicos asociados | C32: 3
B33: 3 objetivos estratégicos asociados | C33: 4
B34: 4 o más objetivos estratégicos asociados | C34: 5
B36: Resultados auditorías anteriores
B37: Sin hallazgos | C37: 1
B38: 1 a 2 hallazgos | C38: 2
B39: 3 a 4 hallazgos | C39: 3
B40: 5 a 6 hallazgos | C40: 4
B41: 7 o más hallazgos | C41: 5
B45: Nivel de criticidad
B46: Bajo | C46: < 1.5 | D46: Verde | E46: 0 | F46: 1.5 | G46: Bajo
B47: Bajo (Priorizado) | C47: >=1.5 <2 | D47: Verde | E47: =F46 -> 1.5 | F47: 2 | G47: Bajo (Priorizado)
B48: Moderado | C48: >=2 <3 | D48: Amarillo | E48: =F47 -> 2 | F48: 3 | G48: Moderado
B49: Alto | C49: >=3 <4 | D49: Naranja | E49: =F48 -> 3 | F49: 4 | G49: Alto
B50: Extremo | C50: >= 4 | D50: Rojo | E50: 4 | F50: 5 | G50: Extremo
B53: Ciclo de rotación
B54: Bajo | C54: No auditar | D54: < 1.5
B55: Bajo (Priorizado) | C55: Cada 4 años | D55: >=1.5 <2
...

Sheet Priorización 
C1: FORMATO UNIVERSO DE AUDITORÍA BASADA EN RIESGOS OCI | W1: CÓDIGO | X1: EM-FO-008
W2: VERSIÓN | X2: 02
W3: FECHA | X3: 45712
A4: Proceso: Evaluación Control y Mejora
A5: Documento de referencia: Procedimiento Auditorías internas basadas en riesgos EM-PT-004
U6: FECHA DE ELABORACIÓN: | W6: FECHA DE APROBACIÓN
A7: ASPECTOS EVALUABLES UNIDADES AUDITABLES (Proceso/Territoriales) | C7: RIESGO INHERENTE | H7: RIESGO INHERENTE Ponderación de Riesgos del Proceso Cualitativo | I7: 0.4 | J7: Tiempo transcurrido desde última auditoría (Criterio) | K7: 0.1 | L7: Temas de interés de la Alta Dirección (Criterios) | M7: 0.1 | N7: Cantidad de objetivos estratégicos asociados (Criterios) | O7: 0.1 | P7: Resultados auditorías anteriores internas anteriores (Criterios) | Q7: 0.3 | R7: Ponderación | S7: Nivel de criticidad | T7: Ciclo de Rotación auditorías | U7: Priorización de Auditorías Basadas en Riesgos año 1 | V7: Priorización de Auditorías Basadas en Riesgos año 2 | W7: Priorización de Auditorías Basadas en Riesgos año 3 | X7: Priorización de Auditorías Basadas en Riesgos año 4
C8: Extremo | D8: Alto | E8: Moderado | F8: Bajo | G8: Total | I8: RIESGO INHERENTE Ponderación de Riesgos del Proceso Cuantitativo | K8: Tiempo transcurrido desde última auditoría (Calificación) | M8: Temas de interés de la Alta Dirección - Calificación | O8: Cantidad de objetivos estratégicos asociados (Calificación) | Q8: Resultados auditorías anteriores internas y externas (Calificación)
A9: 1 | G9: =SUM(C9:F9) -> 0 | H9: =IF(C9>=1,"Extremo",IF(D9>=1,"Alto",IF(E9>=1,"Moderado",IF(F9>=1,"Bajo",IF(G9=0,"Bajo"))))) -> Bajo | I9: =IF(C9>=1,5,IF(D9>=1,4,IF(E9>=1,3,IF(F9>=1,2,IF(G9=0,1))))) -> 1 | J9: <= 1 año | K9: =INDEX(Tiempo_Ult_Aud_Calif,MATCH('Priorización '!J9,Tiempo_Ult_Aud_Def,0)) -> 1 | L9: Interés medio | M9: =INDEX(Nivel_Directivo_Calif,MATCH(L9,Nivel_Directivo_Def,0)) -> 3 | N9: No tiene objetivo asociado | O9: =INDEX(Impacto_Obj_Est_Calif,MATCH(N9,Impacto_Obj_Est_Def,0)) -> 1 | P9: Sin hallazgos | Q9: =INDEX(Result_Aud_Ant_Calif,MATCH(P9,Result_Aud_Ant_Def,0)) -> 1 | R9: =$I$7*I9+$K$7*K9+$M$7*M9+$O$7*O9+$Q$7*Q9 -> 1.2 | S9: =LOOKUP(R9,Nivel_Criticidad) -> Bajo | T9: =INDEX(Ciclo_Rotación_Calif,MATCH(S9,Ciclo_Rotación_Def,0)) -> No auditar | U9: =IF(T9="Cada año",B9,"") | V9: =IF(OR(T9="Cada año",T9="Cada 2 años"),B9,"") | W9: =IF(OR(T9="Cada año",T9="Cada 3 años"),B9,"") | X9: =IF(OR(T9="Cada año",T9="Cada 2 años",T9="Cada 4 años"),B9,"")
A10: 2 | G10: =SUM(C10:F10) -> 0 | H10: =IF(C10>=1,"Extremo",IF(D10>=1,"Alto",IF(E10>=1,"Moderado",IF(F10>=1,"Bajo",IF(G10=0,"Bajo"))))) -> Bajo | I10: =IF(C10>=1,5,IF(D10>=1,4,IF(E10>=1,3,IF(F10>=1,2,IF(G10=0,1))))) -> 1 | J10: > 1 año <= 2 años | K10: =INDEX(Tiempo_Ult_Aud_Calif,MATCH('Priorización '!J10,Tiempo_Ult_Aud_Def,0)) -> 2 | L10: Interés bajo | M10: =INDEX(Nivel_Directivo_Calif,MATCH(L10,Nivel_Directivo_Def,0)) -> 2 | N10: 4 o más objetivos estratégicos asociados | O10: =INDEX(Impacto_Obj_Est_Calif,MATCH(N10,Impacto_Obj_Est_Def,0)) -> 5 | P10: Sin hallazgos | Q10: =INDEX(Result_Aud_Ant_Calif,MATCH(P10,Result_Aud_Ant_Def,0)) -> 1 | R10: =$I$7*I10+$K$7*K10+$M$7*M10+$O$7*O10+$Q$7*Q10 -> 1.6 | S10: =LOOKUP(R10,Nivel_Criticidad) -> Bajo (Priorizado) | T10: =INDEX(Ciclo_Rotación_Calif,MATCH(S10,Ciclo_Rotación_Def,0)) -> Cada 4 años | U10: =IF(T10="Cada año",B10,"") | V10: =IF(OR(T10="Cada año",T10="Cada 2 años"),B10,"") | W10: =IF(OR(T10="Cada año",T10="Cada 3 años"),B10,"") | X10: =IF(OR(T10="Cada año",T10="Cada 2 años",T10="Cada 4 años"),B10,"") -> 0
A11: 3 | G11: =SUM(C11:F11) -> 0 | H11: =IF(C11>=1,"Extremo",IF(D11>=1,"Alto",IF(E11>=1,"Moderado",IF(F11>=1,"Bajo",IF(G11=0,"Bajo"))))) -> Bajo | I11: =IF(C11>=1,5,IF(D11>=1,4,IF(E11>=1,3,IF(F11>=1,2,IF(G11=0,1))))) -> 1 | J11: > 3 años <= 4 años | K11: =INDEX(Tiempo_Ult_Aud_Calif,MATCH('Priorización '!J11,Tiempo_Ult_Aud_Def,0)) -> 4 | L11: Interés muy relevante | M11: =INDEX(Nivel_Directivo_Calif,MATCH(L11,Nivel_Directivo_Def,0)) -> 5 | N11: 2 objetivos estratégicos asociados | O11: =INDEX(Impacto_Obj_Est_Calif,MATCH(N11,Impacto_Obj_Est_Def,0)) -> 3 | P11: Sin hallazgos | Q11: =INDEX(Result_Aud_Ant_Calif,MATCH(P11,Result_Aud_Ant_Def,0)) -> 1 | R11: =$I$7*I11+$K$7*K11+$M$7*M11+$O$7*O11+$Q$7*Q11 -> 1.9 | S11: =LOOKUP(R11,Nivel_Criticidad) -> Bajo (Priorizado) | T11: =INDEX(Ciclo_Rotación_Calif,MATCH(S11,Ciclo_Rotación_Def,0)) -> Cada 4 años | U11: =IF(T11="Cada año",B11,"") | V11: =IF(OR(T11="Cada año",T11="Cada 2 años"),B11,"") | W11: =IF(OR(T11="Cada año",T11="Cada 3 años"),B11,"") | X11: =IF(OR(T11="Cada año",T11="Cada 2 años",T11="Cada 4 años"),B11,"") -> 0
A12: 4 | G12: =SUM(C12:F12) -> 0 | H12: =IF(C12>=1,"Extremo",IF(D12>=1,"Alto",IF(E12>=1,"Moderado",IF(F12>=1,"Bajo",IF(G12=0,"Bajo"))))) -> Bajo | I12: =IF(C12>=1,5,IF(D12>=1,4,IF(E12>=1,3,IF(F12>=1,2,IF(G12=0,1))))) -> 1 | J12: > 4 años | K12: =INDEX(Tiempo_Ult_Aud_Calif,MATCH('Priorización '!J12,Tiempo_Ult_Aud_Def,0)) -> 5 | L12: Interés bajo | M12: =INDEX(Nivel_Directivo_Calif,MATCH(L12,Nivel_Directivo_Def,0)) -> 2 | N12: 1 objetivo estratégico asociado | O12: =INDEX(Impacto_Obj_Est_Calif,MATCH(N12,Impacto_Obj_Est_Def,0)) -> 2 | P12: 1 a 2 hallazgos | Q12: =INDEX(Result_Aud_Ant_Calif,MATCH(P12,Result_Aud_Ant_Def,0)) -> 2 | R12: =$I$7*I12+$K$7*K12+$M$7*M12+$O$7*O12+$Q$7*Q12 -> 1.9 | S12: =LOOKUP(R12,Nivel_Criticidad) -> Bajo (Priorizado) | T12: =INDEX(Ciclo_Rotación_Calif,MATCH(S12,Ciclo_Rotación_Def,0)) -> Cada 4 años | U12: =IF(T12="Cada año",B12,"") | V12: =IF(OR(T12="Cada año",T12="Cada 2 años"),B12,"") | W12: =IF(OR(T12="Cada año",T12="Cada 3 años"),B12,"") | X12: =IF(OR(T12="Cada año",T12="Cada 2 años",T12="Cada 4 años"),B12,"") -> 0
A13: 5 | G13: =SUM(C13:F13) -> 0 | H13: =IF(C13>=1,"Extremo",IF(D13>=1,"Alto",IF(E13>=1,"Moderado",IF(F13>=1,"Bajo",IF(G13=0,"Bajo"))))) -> Bajo | I13: =IF(C13>=1,5,IF(D13>=1,4,IF(E13>=1,3,IF(F13>=1,2,IF(G13=0,1))))) -> 1 | J13: <= 1 año | K13: =INDEX(Tiempo_Ult_Aud_Calif,MATCH('Priorización '!J13,Tiempo_Ult_Aud_Def,0)) -> 1 | L13: Interés muy relevante | M13: =INDEX(Nivel_Directivo_Calif,MATCH(L13,Nivel_Directivo_Def,0)) -> 5 | N13: 2 objetivos estratégicos asociados | O13: =INDEX(Impacto_Obj_Est_Calif,MATCH(N13,Impacto_Obj_Est_Def,0)) -> 3 | P13: Sin hallazgos | Q13: =INDEX(Result_Aud_Ant_Calif,MATCH(P13,Result_Aud_Ant_Def,0)) -> 1 | R13: =$I$7*I13+$K$7*K13+$M$7*M13+$O$7*O13+$Q$7*Q13 -> 1.6 | S13: =LOOKUP(R13,Nivel_Criticidad) -> Bajo (Priorizado) | T13: =INDEX(Ciclo_Rotación_Calif,MATCH(S13,Ciclo_Rotación_Def,0)) -> Cada 4 años | U13: =IF(T13="Cada año",B13,"") | V13: =IF(OR(T13="Cada año",T13="Cada 2 años"),B13,"") | W13: =IF(OR(T13="Cada año",T13="Cada 3 años"),B13,"") | X13: =IF(OR(T13="Cada año",T13="Cada 2 años",T13="Cada 4 años"),B13,"") -> 0
A14: 6 | G14: =SUM(C14:F14) -> 0 | H14: =IF(C14>=1,"Extremo",IF(D14>=1,"Alto",IF(E14>=1,"Moderado",IF(F14>=1,"Bajo",IF(G14=0,"Bajo"))))) -> Bajo | I14: =IF(C14>=1,5,IF(D14>=1,4,IF(E14>=1,3,IF(F14>=1,2,IF(G14=0,1))))) -> 1 | J14: <= 1 año | K14: =INDEX(Tiempo_Ult_Aud_Calif,MATCH('Priorización '!J14,Tiempo_Ult_Aud_Def,0)) -> 1 | L14: Interés muy relevante | M14: =INDEX(Nivel_Directivo_Calif,MATCH(L14,Nivel_Directivo_Def,0)) -> 5 | N14: 4 o más objetivos estratégicos asociados | O14: =INDEX(Impacto_Obj_Est_Calif,MATCH(N14,Impacto_Obj_Est_Def,0)) -> 5 | P14: 5 a 6 hallazgos | Q14: =INDEX(Result_Aud_Ant_Calif,MATCH(P14,Result_Aud_Ant_Def,0)) -> 4 | R14: =$I$7*I14+$K$7*K14+$M$7*M14+$O$7*O14+$Q$7*Q14 -> 2.7 | S14: =LOOKUP(R14,Nivel_Criticidad) -> Moderado | T14: =INDEX(Ciclo_Rotación_Calif,MATCH(S14,Ciclo_Rotación_Def,0)) -> Cada 3 años | U14: =IF(T14="Cada año",B14,"") | V14: =IF(OR(T14="Cada año",T14="Cada 2 años"),B14,"") | W14: =IF(OR(T14="Cada año",T14="Cada 3 años"),B14,"") -> 0 | X14: =IF(OR(T14="Cada año",T14="Cada 2 años",T14="Cada 4 años"),B14,"")
A15: 7 | G15: =SUM(C15:F15) -> 0 | H15: =IF(C15>=1,"Extremo",IF(D15>=1,"Alto",IF(E15>=1,"Moderado",IF(F15>=1,"Bajo",IF(G15=0,"Bajo"))))) -> Bajo | I15: =IF(C15>=1,5,IF(D15>=1,4,IF(E15>=1,3,IF(F15>=1,2,IF(G15=0,1))))) -> 1 | J15: > 2 años <= 3 años | K15: =INDEX(Tiempo_Ult_Aud_Calif,MATCH('Priorización '!J15,Tiempo_Ult_Aud_Def,0)) -> 3 | L15: Interés muy relevante | M15: =INDEX(Nivel_Directivo_Calif,MATCH(L15,Nivel_Directivo_Def,0)) -> 5 | N15: 3 objetivos estratégicos asociados | O15: =INDEX(Impacto_Obj_Est_Calif,MATCH(N15,Impacto_Obj_Est_Def,0)) -> 4 | P15: 1 a 2 hallazgos | Q15: =INDEX(Result_Aud_Ant_Calif,MATCH(P15,Result_Aud_Ant_Def,0)) -> 2 | R15: =$I$7*I15+$K$7*K15+$M$7*M15+$O$7*O15+$Q$7*Q15 -> 2.2 | S15: =LOOKUP(R15,Nivel_Criticidad) -> Moderado | T15: =INDEX(Ciclo_Rotación_Calif,MATCH(S15,Ciclo_Rotación_Def,0)) -> Cada 3 años | U15: =IF(T15="Cada año",B15,"") | V15: =IF(OR(T15="Cada año",T15="Cada 2 años"),B15,"") | W15: =IF(OR(T15="Cada año",T15="Cada 3 años"),B15,"") -> 0 | X15: =IF(OR(T15="Cada año",T15="Cada 2 años",T15="Cada 4 años"),B15,"")
A16: 8 | G16: =SUM(C16:F16) -> 0 | H16: =IF(C16>=1,"Extremo",IF(D16>=1,"Alto",IF(E16>=1,"Moderado",IF(F16>=1,"Bajo",IF(G16=0,"Bajo"))))) -> Bajo | I16: =IF(C16>=1,5,IF(D16>=1,4,IF(E16>=1,3,IF(F16>=1,2,IF(G16=0,1))))) -> 1 | J16: <= 1 año | K16: =INDEX(Tiempo_Ult_Aud_Calif,MATCH('Priorización '!J16,Tiempo_Ult_Aud_Def,0)) -> 1 | L16: Interés alto | M16: =INDEX(Nivel_Directivo_Calif,MATCH(L16,Nivel_Directivo_Def,0)) -> 4 | N16: 2 objetivos estratégicos asociados | O16: =INDEX(Impacto_Obj_Est_Calif,MATCH(N16,Impacto_Obj_Est_Def,0)) -> 3 | P16: 5 a 6 hallazgos | Q16: =INDEX(Result_Aud_Ant_Calif,MATCH(P16,Result_Aud_Ant_Def,0)) -> 4 | R16: =$I$7*I16+$K$7*K16+$M$7*M16+$O$7*O16+$Q$7*Q16 -> 2.4 | S16: =LOOKUP(R16,Nivel_Criticidad) -> Moderado | T16: =INDEX(Ciclo_Rotación_Calif,MATCH(S16,Ciclo_Rotación_Def,0)) -> Cada 3 años | U16: =IF(T16="Cada año",B16,"") | V16: =IF(OR(T16="Cada año",T16="Cada 2 años"),B16,"") | W16: =IF(OR(T16="Cada año",T16="Cada 3 años"),B16,"") -> 0 | X16: =IF(OR(T16="Cada año",T16="Cada 2 años",T16="Cada 4 años"),B16,"")
A17: 9 | G17: =SUM(C17:F17) -> 0 | H17: =IF(C17>=1,"Extremo",IF(D17>=1,"Alto",IF(E17>=1,"Moderado",IF(F17>=1,"Bajo",IF(G17=0,"Bajo"))))) -> Bajo | I17: =IF(C17>=1,5,IF(D17>=1,4,IF(E17>=1,3,IF(F17>=1,2,IF(G17=0,1))))) -> 1 | J17: > 1 año <= 2 años | K17: =INDEX(Tiempo_Ult_Aud_Calif,MATCH('Priorización '!J17,Tiempo_Ult_Aud_Def,0)) -> 2 | L17: Interés alto | M17: =INDEX(Nivel_Directivo_Calif,MATCH(L17,Nivel_Directivo_Def,0)) -> 4 | N17: 2 objetivos estratégicos asociados | O17: =INDEX(Impacto_Obj_Est_Calif,MATCH(N17,Impacto_Obj_Est_Def,0)) -> 3 | P17: 1 a 2 hallazgos | Q17: =INDEX(Result_Aud_Ant_Calif,MATCH(P17,Result_Aud_Ant_Def,0)) -> 2 | R17: =$I$7*I17+$K$7*K17+$M$7*M17+$O$7*O17+$Q$7*Q17 -> 1.9 | S17: =LOOKUP(R17,Nivel_Criticidad) -> Bajo (Priorizado) | T17: =INDEX(Ciclo_Rotación_Calif,MATCH(S17,Ciclo_Rotación_Def,0)) -> Cada 4 años | U17: =IF(T17="Cada año",B17,"") | V17: =IF(OR(T17="Cada año",T17="Cada 2 años"),B17,"") | W17: =IF(OR(T17="Cada año",T17="Cada 3 años"),B17,"") | X17: =IF(OR(T17="Cada año",T17="Cada 2 años",T17="Cada 4 años"),B17,"") -> 0
A18: 10 | G18: =SUM(C18:F18) -> 0 | H18: =IF(C18>=1,"Extremo",IF(D18>=1,"Alto",IF(E18>=1,"Moderado",IF(F18>=1,"Bajo",IF(G18=0,"Bajo"))))) -> Bajo | I18: =IF(C18>=1,5,IF(D18>=1,4,IF(E18>=1,3,IF(F18>=1,2,IF(G18=0,1))))) -> 1 | J18: > 3 años <= 4 años | K18: =INDEX(Tiempo_Ult_Aud_Calif,MATCH('Priorización '!J18,Tiempo_Ult_Aud_Def,0)) -> 4 | L18: Interés alto | M18: =INDEX(Nivel_Directivo_Calif,MATCH(L18,Nivel_Directivo_Def,0)) -> 4 | N18: 1 objetivo estratégico asociado | O18: =INDEX(Impacto_Obj_Est_Calif,MATCH(N18,Impacto_Obj_Est_Def,0)) -> 2 | P18: 1 a 2 hallazgos | Q18: =INDEX(Result_Aud_Ant_Calif,MATCH(P18,Result_Aud_Ant_Def,0)) -> 2 | R18: =$I$7*I18+$K$7*K18+$M$7*M18+$O$7*O18+$Q$7*Q18 -> 2 | S18: =LOOKUP(R18,Nivel_Criticidad) -> Moderado | T18: =INDEX(Ciclo_Rotación_Calif,MATCH(S18,Ciclo_Rotación_Def,0)) -> Cada 3 años | U18: =IF(T18="Cada año",B18,"") | V18: =IF(OR(T18="Cada año",T18="Cada 2 años"),B18,"") | W18: =IF(OR(T18="Cada año",T18="Cada 3 años"),B18,"") -> 0 | X18: =IF(OR(T18="Cada año",T18="Cada 2 años",T18="Cada 4 años"),B18,"")
A19: 11 | G19: =SUM(C19:F19) -> 0 | H19: =IF(C19>=1,"Extremo",IF(D19>=1,"Alto",IF(E19>=1,"Moderado",IF(F19>=1,"Bajo",IF(G19=0,"Bajo"))))) -> Bajo | I19: =IF(C19>=1,5,IF(D19>=1,4,IF(E19>=1,3,IF(F19>=1,2,IF(G19=0,1))))) -> 1 | J19: > 1 año <= 2 años | K19: =INDEX(Tiempo_Ult_Aud_Calif,MATCH('Priorización '!J19,Tiempo_Ult_Aud_Def,0)) -> 2 | L19: Interés muy relevante | M19: =INDEX(Nivel_Directivo_Calif,MATCH(L19,Nivel_Directivo_Def,0)) -> 5 | N19: 1 objetivo estratégico asociado | O19: =INDEX(Impacto_Obj_Est_Calif,MATCH(N19,Impacto_Obj_Est_Def,0)) -> 2 | P19: 1 a 2 hallazgos | Q19: =INDEX(Result_Aud_Ant_Calif,MATCH(P19,Result_Aud_Ant_Def,0)) -> 2 | R19: =$I$7*I19+$K$7*K19+$M$7*M19+$O$7*O19+$Q$7*Q19 -> 1.9 | S19: =LOOKUP(R19,Nivel_Criticidad) -> Bajo (Priorizado) | T19: =INDEX(Ciclo_Rotación_Calif,MATCH(S19,Ciclo_Rotación_Def,0)) -> Cada 4 años | U19: =IF(T19="Cada año",B19,"") | V19: =IF(OR(T19="Cada año",T19="Cada 2 años"),B19,"") | W19: =IF(OR(T19="Cada año",T19="Cada 3 años"),B19,"") | X19: =IF(OR(T19="Cada año",T19="Cada 2 años",T19="Cada 4 años"),B19,"") -> 0
A20: 12 | G20: =SUM(C20:F20) -> 0 | H20: =IF(C20>=1,"Extremo",IF(D20>=1,"Alto",IF(E20>=1,"Moderado",IF(F20>=1,"Bajo",IF(G20=0,"Bajo"))))) -> Bajo | I20: =IF(C20>=1,5,IF(D20>=1,4,IF(E20>=1,3,IF(F20>=1,2,IF(G20=0,1))))) -> 1 | J20: > 4 años | K20: =INDEX(Tiempo_Ult_Aud_Calif,MATCH('Priorización '!J20,Tiempo_Ult_Aud_Def,0)) -> 5 | L20: Interés muy relevante | M20: =INDEX(Nivel_Directivo_Calif,MATCH(L20,Nivel_Directivo_Def,0)) -> 5 | N20: 4 o más objetivos estratégicos asociados | O20: =INDEX(Impacto_Obj_Est_Calif,MATCH(N20,Impacto_Obj_Est_Def,0)) -> 5 | P20: 1 a 2 hallazgos | Q20: =INDEX(Result_Aud_Ant_Calif,MATCH(P20,Result_Aud_Ant_Def,0)) -> 2 | R20: =$I$7*I20+$K$7*K20+$M$7*M20+$O$7*O20+$Q$7*Q20 -> 2.5 | S20: =LOOKUP(R20,Nivel_Criticidad) -> Moderado | T20: =INDEX(Ciclo_Rotación_Calif,MATCH(S20,Ciclo_Rotación_Def,0)) -> Cada 3 años | U20: =IF(T20="Cada año",B20,"") | V20: =IF(OR(T20="Cada año",T20="Cada 2 años"),B20,"") | W20: =IF(OR(T20="Cada año",T20="Cada 3 años"),B20,"") -> 0 | X20: =IF(OR(T20="Cada año",T20="Cada 2 años",T20="Cada 4 años"),B20,"")
... A38: 30 | G38: =SUM(C38:F38) -> 0 | H38: =IF(C38>=1,"Extremo",IF(D38>=1,"Alto",IF(E38>=1,"Moderado",IF(F38>=1,"Bajo",IF(G38=0,"Bajo"))))) -> Bajo | I38: =IF(C38>=1,5,IF(D38>=1,4,IF(E38>=1,3,IF(F38>=1,2,IF(G38=0,1))))) -> 1 | J38: > 4 años | K38: =INDEX(Tiempo_Ult_Aud_Calif,MATCH('Priorización '!J38,Tiempo_Ult_Aud_Def,0)) -> 5 | L38: Interés alto | M38: =INDEX(Nivel_Directivo_Calif,MATCH(L38,Nivel_Directivo_Def,0)) -> 4 | N38: 4 o más objetivos estratégicos asociados | O38: =INDEX(Impacto_Obj_Est_Calif,MATCH(N38,Impacto_Obj_Est_Def,0)) -> 5 | P38: 7 o más hallazgos | Q38: =INDEX(Result_Aud_Ant_Calif,MATCH(P38,Result_Aud_Ant_Def,0)) -> 5 | R38: =$I$7*I38+$K$7*K38+$M$7*M38+$O$7*O38+$Q$7*Q38 -> 3.3 | S38: =LOOKUP(R38,Nivel_Criticidad) -> Alto | T38: =INDEX(Ciclo_Rotación_Calif,MATCH(S38,Ciclo_Rotación_Def,0)) -> Cada 2 años | U38: =IF(T38="Cada año",B38,"") | V38: =IF(OR(T38="Cada año",T38="Cada 2 años"),B38,"") -> 0 | W38: =IF(OR(T38="Cada año",T38="Cada 3 años"),B38,"") | X38: =IF(OR(T38="Cada año",T38="Cada 2 años",T38="Cada 4 años"),B38,"") -> 0
G39: , | H39: =IF(C39>=1,"Extremo",IF(D39>=1,"Alto",IF(E39>=1,"Moderado",IF(F39>=1,"Bajo",IF(G39=0,"Bajo"))))) -> FALSE | I39: =IF(C39>=1,5,IF(D39>=1,4,IF(E39>=1,3,IF(F39>=1,2,IF(G39=0,1))))) -> FALSE

Sheet Instructivo
B1: FORMATO UNIVERSO DE AUDITORÍA BASADA EN RIESGOS OCI | E1: CÓDIGO | F1: =+'Priorización '!X1 -> EM-FO-008
E2: VERSIÓN | F2: =+'Priorización '!X2 -> 02
E3: FECHA | F3: =+'Priorización '!X3 -> 45712
A4: Proceso: Evaluación Control y Mejora
A5: Documento de referencia: Procedimiento Auditorías internas basadas en riesgos EM-PT-004
A6: UNIVERSO DE AUDITORÍA BASADA EN RIESGOS (instrucciones para su diligenciamiento)
A7: CONCEPTO | B7: DESCRIPCIÓN
A8: Aspectos evaluables unidades auditables (proceso/territoriales) | B8: Tambien son conocidos como unidades auditables, son todos aquellos aspectos que pueden ser evaluados o auditados y que se convertirán en un informe de auditoría.
A9: Riesgo inherente | B9: Digite la cantidad de riesgos por nivel que tiene cada aspecto evaluable.
A10: Total | B10: No se debe diligenciar esta columna, aparecerá automáticamente el puntaje consolidado del total del riesgos que afecta cada aspecto evaluable resultado de la cantidad de riesgos por nivel (extremo, alto, moderado, bajo) .
A11: RIESGO INHERENTE Ponderación de Riesgos del Proceso Cualitativo | B11: No se debe diligenciar esta columna, aparecerá automáticamente el nivel de riesgo poderado o consolidado para cada aspecto evaluable (unidad auditable).
A12: RIESGO INHERENTE Ponderación de Riesgos del Proceso Cuantitativo | B12: No se debe diligenciar esta columna, aparecerá automáticamente la calificación que obtiene el nivel de riesgo inherente consolidado o poderado.
A13: Tiempo transcurrido desde última auditoría (Criterio) | B13: Seleccione de la lista desplegable los años transcurridos desde la última auditoría o en aso que nunca se haya auditado seleccione > 4 años.
A14: Tiempo transcurrido desde última auditoría (Calificación) | B14: No se debe diligenciar esta columna, aparecerá automáticamente la calificación que obtiene el nivel de riesgo inherente consolidado o poderado.
A15: Temas de interés de la Alta Dirección (Criterios) | B15: Describa la tarea que se propone realizar para eliminar las causas del hallazgo,ejemplo capacitaciones. Campo que debe ser diligenciado por el auditado.
A16: Temas de interés de la Alta Dirección - Calificación | B16: No se debe diligenciar esta columna, aparecerá automáticamente la calificación respecto de los intereses de la alta dirección
A17: Cantidad de objetivos estratégicos asociados (Criterios) | B17: Seleccionar la opción que corresponda a la insidencia de este aspecto evaluable o temática en los objetivos estratégicos.
A18: Cantidad de objetivos estratégicos asociados (Calificación) | B18: No se debe diligenciar esta columna, aparecerá automáticamente al diligenciar la columna anterior "Cantidad de objetivos estratégicos asociados (Criterios)".
... A27: Priorización de Auditorías Basadas en Riesgos año 4 | B27: No se debe diligenciar esta columna, acá aparecerá automáticamente las unidades auditables que deben formar parte del plan anual de auditorías del cuarto año, acorde con el ciclo de rotación de auditorías, el cual es aprobado por el Comité Institucional de Coordinación de Control Interno.

Sheet Procesos A Auditar Vs Recursos
B2: DETERMINACION PLAN DE AUDITORIA vs RECURSOS
B5: Fecha de Elaboración:
B7: Nombre del Subproceso A Auditar de Acuerdo a la Evaluación del Universo | C7: Detalle del Alcance del Trabajo | D7: Tipo de Trabajo | E7: Tiempo Estimado de la Auditoria (hh). | F7: Incluido en el Plan Anual
B9: Gestión Humana | D9: Aseguramiento | E9: 10 | F9: No
B11: Gestión Humana | D11: Aseguramiento | E11: 10 | F11: Si
B14: TOTAL HORAS NECESARIAS | E14: =SUM(E9:E13) -> 20
B15: TOTAL HORAS DISPONIBLES EQUIPO DE AUDITORES
B16: DIFERENCIA (TIEMPO ADECUADO / TIEMPO INSUFICIENTE)
B17: Observaciones Generales:
B21: Fuente: Adaptado de Instituto de Auditores Internos. COSO ERM. Agosto 2014.

Sheet Seguimiento Programa Anual
B2: SEGUIMIENTO PROGRAMA ANUAL DE AUDITORIA
B5: Objetivo del Documento:
B6: Fecha de Elaboración:
B8: Nombre del proceso/proyecto/Procedimiento A Auditar de Acuerdo a la Evaluación del Universo | C8: Detalle del Alcance del Trabajo | D8: Tipo de Trabajo | E8: Tiempo Estimado de la Auditoria (hh). | F8: Fecha de Inicio | G8: Fecha de Finalización | H8: AVANCES
H9: Estado | I9: Ene | J9: Feb | K9: Mar | L9: Abr | M9: May | N9: Jun | O9: Jul | P9: Ago | Q9: Sep | R9: Oct | S9: Nov | T9: Dic
B10: Gestión Humana | D10: Aseguramiento | H10: Sin Iniciar
H11: Sin Iniciar
H12: Sin Iniciar
H13: Sin Iniciar
H14: Sin Iniciar
B15: TOTAL HORAS NECESARIAS | E15: =SUM(E10:E14) -> 0
B16: TOTAL HORAS DISPONIBLES EQUIPO DE AUDITORES
B17: DIFERENCIA (TIEMPO ADECUADO / TIEMPO INSUFICIENTE) | E17: =+E16-E15 -> 0
B18: Observaciones Generales:
B22: Fuente: Adaptado de Instituto de Auditores Internos. COSO ERM. Agosto 2014.

Sheet Hoja1
B3: Extremo | C3: Adecuado | D3: =+CONCATENATE(B3,C3) -> ExtremoAdecuado | E3: 1 año
B4: Alto | C4: Adecuado | D4: =+CONCATENATE(B4,C4) -> AltoAdecuado | E4: 2 años
B5: Moderado | C5: Adecuado | D5: =+CONCATENATE(B5,C5) -> ModeradoAdecuado | E5: 3 años
B6: Bajo | C6: Adecuado | D6: =+CONCATENATE(B6,C6) -> BajoAdecuado | E6: 4 años
B7: Muy Bajo | C7: Adecuado | D7: =+CONCATENATE(B7,C7) -> Muy BajoAdecuado | E7: 5 años
B8: Extremo | C8: Inadecuado | D8: =+CONCATENATE(B8,C8) -> ExtremoInadecuado | E8: 1 año
B9: Alto | C9: Inadecuado | D9: =+CONCATENATE(B9,C9) -> AltoInadecuado | E9: 1 año
B10: Moderado | C10: Inadecuado | D10: =+CONCATENATE(B10,C10) -> ModeradoInadecuado | E10: 2 años
B11: Bajo | C11: Inadecuado | D11: =+CONCATENATE(B11,C11) -> BajoInadecuado | E11: 3 años
B12: Muy Bajo | C12: Inadecuado | D12: =+CONCATENATE(B12,C12) -> Muy BajoInadecuado | E12: 4 años
